Workbook

Sheet Summary
A1: SATOSHI STOP LOSS — Insurance Fund Sizing
A2: Key Findings & Recommendation
A4: THE CORE QUESTION
A5: "Would a 1% enrollment fee do it — or do we need 5%?"
A7: REQUIRED IF / TVL BY SCENARIO (Base Case: $1B TVL, 60% BTC in vaults)
A8: Scenario | B8: IF / TVL Needed | C8: IF$ at $1B TVL | D8: 1% Enrollment? | E8: Key Driver
A9: Scenario A: Small (1K BTC) | B9: ~1.2% | C9: ~$12M | D9: ✅ YES — barely | E9: Tier 1 IF absorption loss
A10: Scenario B: Moderate (10K BTC) | B10: ~4.3% | C10: ~$43M | D10: ⚠️ NO — need 4–5% | E10: DEX slippage dominates
A11: Scenario C: Large (100K BTC) | B11: ~8.0% | C11: ~$80M | D11: 🔴 NO — need 8%+ | E11: All 3 tiers stressed
A12: Scenario D: Catastrophic (500K BTC) | B12: ~11.4% | C12: ~$114M | D12: 🚨 NO — need 11%+ | E12: Reinsurance layer activates
A14: THE ANSWER
A15: 1. 1% enrollment alone | C15: Covers ONLY a small Satoshi signal (Scenario A). A 1% one-time fee leaves you ~3–4× undercapitalized for a moderate dump event. It's not enough on its own.
A16: 2. Recommended: 0.50% enrollment + 10 bps/yr ongoing | C16: Builds IF to ~5% of TVL in ~3 years at $1B TVL (with $5M seed). Covers 80% of realistic scenarios. Stakers earn 3–6% APY from premium inflows.
A17: 3. For full tail protection (Scenarios C/D) | C17: Need 8–12% IF/TVL. Achieved via: seed capital + reinsurance layer + governance-set TVL cap in early phases. Not achievable through fees alone — designed as multi-year buildup.
A18: 4. Protocol design implication | C18: Launch with TVL cap tied to IF size (e.g., max TVL = IF × 20). Expand cap as IF grows. This is standard practice for DeFi insurance protocols (Nexus Mutual model).
A20: MARKET CONTEXT (April 4, 2026 — Live Research)
A21: BTC Price | C21: $67,000
A22: Satoshi Holdings (Patoshi High) | C22: 1.1M BTC ≈ $73.7B (5.54% of supply)
A23: Satoshi Holdings (BitMEX Low Est.) | C23: 700K BTC ≈ $46.9B (3.52% of supply)
A24: BTC Daily Spot Volume | C24: ~$25B central estimate; range $8B–$36B
A25: Order Book Depth ±2% (all CEXes) | C25: ~$100M aggregate — thin vs Satoshi holdings
A26: FTX Collapse (closest analogue) | C26: -17% in 24h, -25% peak over 3 days
A27: LUNA Crash | C27: -22% in 24h, -58% peak over 7 days
A28: Nexus Mutual Premium (2025) | C28: Dropped below 1%/yr for select protocols — validates our fee range
A30: Model v1.0 | April 4, 2026 | Satoshi Stop Loss Protocol | Pre-Seed — Internal Use Only

Sheet Assumptions
A1: SATOSHI STOP LOSS — IF Sizing Model | Assumptions
A2: Blue cells = inputs | Black cells = formulas | Green = cross-sheet links
A4: BTC MARKET DATA (April 4, 2026)
A5: Parameter | B5: Value | C5: Unit | D5: Source / Notes
A6: BTC Price | B6: 67000 | C6: USD/BTC | D6: CoinGecko / CoinMarketCap, April 4 2026
A7: BTC Circulating Supply | B7: 19870000 | C7: BTC | D7: CoinMarketCap, April 2026
A8: BTC Market Cap | B8: =B7*B6 -> 1331290000000 | C8: $ | D8: Calculated
A9: Daily Spot Volume (central) | B9: 25000000000 | C9: $ | D9: Avg of $8B–$36B range; wide spread across CEXes
A10: Daily Volume — Bear | B10: 8000000000 | C10: $ | D10: Low-end reported; thin liquidity scenario
A11: Daily Volume — Bull | B11: 40000000000 | C11: $ | D11: High-end; deep market scenario
A12: Order Book Depth ±2% (agg.) | B12: 100000000 | C12: $ | D12: CoinGlass / CoinGecko 2025; all major CEXes
A13: Order Book Depth ±1% (agg.) | B13: 25000000 | C13: $ | D13: Est. ~25% of ±2% depth bucket
A14: BTC Daily Volatility (norm.) | B14: 0.04 | C14: %/day | D14: Historical avg; 3–5% on normal days
A15: Panic Volatility Multiplier | B15: 3 | C15: × | D15: Satoshi event = extreme tail; 3× normal vol
A17: SATOSHI NAKAMOTO HOLDINGS
A18: Parameter | B18: Value | C18: Unit | D18: Source / Notes
A19: Holdings — Patoshi High (BTC) | B19: 1100000 | C19: BTC | D19: Arkham / Sergio Lerner; 22,000 blocks × 50 BTC
A20: Holdings — BitMEX Research Low | B20: 700000 | C20: BTC | D20: BitMEX Research; more conservative estimate
A21: Holdings Used in Model | B21: =B19 -> 1100000 | C21: BTC | D21: Patoshi High — worst-case market scenario
A22: Value of Satoshi Holdings | B22: =B21*B6 -> 73700000000 | C22: $ | D22: At current BTC price
A23: As % of Circulating Supply | B23: =B21/B7 -> 0.055359839 | C23: % | D23: Satoshi / total supply
A24: As % of BTC Market Cap | B24: =B22/B8 -> 0.055359839 | C24: % | D24: Satoshi value / market cap
A26: PROTOCOL PARAMETERS
A27: Parameter | B27: Value | C27: Unit | D27: Notes
A28: SSL TVL — Bear Case | B28: 250 | C28: $M | D28: Conservative; early protocol launch
A29: SSL TVL — Base Case | B29: 1000 | C29: $M | D29: Moderate adoption, 12–24 mo post-launch
A30: SSL TVL — Bull Case | B30: 5000 | C30: $M | D30: Strong adoption; institutional onboarding
A31: % BTC-Denominated Vaults | B31: 0.6 | C31: % | D31: BTC likely dominant; governance-adjustable
A32: % ETH-Denominated | B32: 0.25 | C32: % | D32: Second largest expected
A33: % Altcoin / Other | B33: 0.15 | C33: % | D33: Must sum to 100%
A34: Tier 1 (IF Direct) — BTC share | B34: 0.15 | C34: % | D34: IF absorbs first ~15% of BTC positions
A35: Tier 2 (DEX Routing) — BTC share | B35: 0.65 | C35: % | D35: ~65% routed through DEXes
A36: Tier 3 (Auctioneer) — BTC share | B36: 0.2 | C36: % | D36: Residual ~20% via Dutch auction
A37: Oracle Detection Lag | B37: 2 | C37: min | D37: Time from UTXO in mempool → trigger fire
A38: Pre-Trigger Price Decline (est.) | B38: 0.08 | C38: % | D38: Algo traders react before oracle fires
A39: IF BTC Holding Period | B39: 4 | C39: hrs | D39: Hours until IF unwinds absorbed BTC
A41: HISTORICAL BTC CRASH REFERENCE
A42: Event | B42: Date | C42: Trigger | D42: 24h Drop | E42: Peak Drop | F42: Days to Peak
A43: Normal Daily Volatility | B43: — | C43: Baseline | D43: -0.04
A44: Regulatory FUD (China ban) | B44: Sep-21 | C44: Regulatory shock | D44: -0.1 | E44: -0.2 | F44: 7
...

Sheet Dump Scenarios
A1: SATOSHI DUMP SCENARIOS — Price Impact Model
A2: Models 4 scenarios from small Satoshi signal to catastrophic dump
A4: Metric | B4: Scenario A Small (1K BTC) | C4: Scenario B Moderate (10K) | D4: Scenario C Large (100K) | E4: Scenario D Catastrophic (500K)
A5: DUMP SIZE
A6: BTC Sold (coins) | B6: 1000 | C6: 10000 | D6: 100000 | E6: 500000
A7: BTC Sold ($M) | B7: =B6*Assumptions!$B$6/1000000 -> 67 | C7: =C6*Assumptions!$B$6/1000000 -> 670 | D7: =D6*Assumptions!$B$6/1000000 -> 6700 | E7: =E6*Assumptions!$B$6/1000000 -> 33500
A8: % of Satoshi Holdings | B8: =B6/Assumptions!$B$21 -> 0.00090909091 | C8: =C6/Assumptions!$B$21 -> 0.0090909091 | D8: =D6/Assumptions!$B$21 -> 0.090909091 | E8: =E6/Assumptions!$B$21 -> 0.45454545
A9: % of Daily Spot Volume | B9: =B7/(Assumptions!$B$9/1000000) -> 0.00268 | C9: =C7/(Assumptions!$B$9/1000000) -> 0.0268 | D9: =D7/(Assumptions!$B$9/1000000) -> 0.268 | E9: =E7/(Assumptions!$B$9/1000000) -> 1.34
A10: × Aggregate ±2% Order Book Depth | B10: =B7/(Assumptions!$B$11/1000000) -> 0.001675 | C10: =C7/(Assumptions!$B$11/1000000) -> 0.01675 | D10: =D7/(Assumptions!$B$11/1000000) -> 0.1675 | E10: =E7/(Assumptions!$B$11/1000000) -> 0.8375
A12: PRICE IMPACT ASSUMPTIONS (Inputs — calibrated to historical analogues)
A13: Drop at Trigger Fire (incl. oracle lag — before IF acts) | B13: -0.08 | C13: -0.15 | D13: -0.25 | E13: -0.4
A14: Additional Drop During IF Hold (4 hrs after trigger) | B14: -0.05 | C14: -0.15 | D14: -0.25 | E14: -0.35
A15: DEX Execution Slippage — Tier 2 (~5 min window) | B15: -0.01 | C15: -0.05 | D15: -0.1 | E15: -0.15
A16: Auctioneer Shortfall vs pre-event — Tier 3 (30 min) | B16: -0.03 | C16: -0.08 | D16: -0.15 | E16: -0.2
A18: CUMULATIVE PRICE PATH FROM PRE-EVENT
A19: Pre-Event BTC Price ($) | B19: =Assumptions!$B$6 -> 67000 | C19: =Assumptions!$B$6 -> 67000 | D19: =Assumptions!$B$6 -> 67000 | E19: =Assumptions!$B$6 -> 67000
A20: Price at Trigger Fire ($) | B20: =B19*(1+B13) -> 61640 | C20: =C19*(1+C13) -> 56950 | D20: =D19*(1+D13) -> 50250 | E20: =E19*(1+E13) -> 40200
A21: Price After IF Holding Period (~4 hrs) ($) | B21: =B20*(1+B14) -> 58558 | C21: =C20*(1+C14) -> 48407.5 | D21: =D20*(1+D14) -> 37687.5 | E21: =E20*(1+E14) -> 26130
A22: Total Drop: Pre-Event → Trigger Fire | B22: =B13 -> -0.08 | C22: =C13 -> -0.15 | D22: =D13 -> -0.25 | E22: =E13 -> -0.4
A23: Total Drop: Pre-Event → 4-Hour Mark | B23: =(B21/Assumptions!$B$6)-1 -> -0.126 | C23: =(C21/Assumptions!$B$6)-1 -> -0.2775 | D23: =(D21/Assumptions!$B$6)-1 -> -0.4375 | E23: =(E21/Assumptions!$B$6)-1 -> -0.61
A25: ESTIMATED PEAK DROPS (Reference — not used in IF loss calc directly)
A26: Est. 24-Hour Drop from Pre-Event | B26: -0.08 | C26: -0.2 | D26: -0.35 | E26: -0.55
A27: Est. Peak Drop (3–14 day horizon) | B27: -0.15 | C27: -0.35 | D27: -0.6 | E27: -0.8
A28: Est. Recovery Period (months) | B28: 1 | C28: 3 | D28: 12 | E28: 36

Sheet IF Sizing
A1: INSURANCE FUND SIZING — Required Reserve vs. TVL
A2: Required IF ($M) and IF/TVL% for each Satoshi scenario across growth stages
A4: TVL & ASSET MIX (from Assumptions)
A5: Metric | B5: Bear $250M TVL | C5: Base $1B TVL | D5: Growth $2.5B TVL | E5: Bull $5B TVL | F5: Hyper $10B TVL
A6: Protocol TVL ($M) | B6: 250 | C6: 1000 | D6: 2500 | E6: 5000 | F6: 10000
A7: BTC Vaults ($M) [= TVL × BTC%] | B7: =B6*Assumptions!$B$31 -> 150 | C7: =C6*Assumptions!$B$31 -> 600 | D7: =D6*Assumptions!$B$31 -> 1500 | E7: =E6*Assumptions!$B$31 -> 3000 | F7: =F6*Assumptions!$B$31 -> 6000
A8: Tier 1 IF Direct ($M) [BTC × 15%] | B8: =B7*Assumptions!$B$34 -> 22.5 | C8: =C7*Assumptions!$B$34 -> 90 | D8: =D7*Assumptions!$B$34 -> 225 | E8: =E7*Assumptions!$B$34 -> 450 | F8: =F7*Assumptions!$B$34 -> 900
A9: Tier 2 DEX ($M) [BTC × 65%] | B9: =B7*Assumptions!$B$35 -> 97.5 | C9: =C7*Assumptions!$B$35 -> 390 | D9: =D7*Assumptions!$B$35 -> 975 | E9: =E7*Assumptions!$B$35 -> 1950 | F9: =F7*Assumptions!$B$35 -> 3900
A10: Tier 3 Auctioneer ($M) [BTC × 20%] | B10: =B7*Assumptions!$B$36 -> 30 | C10: =C7*Assumptions!$B$36 -> 120 | D10: =D7*Assumptions!$B$36 -> 300 | E10: =E7*Assumptions!$B$36 -> 600 | F10: =F7*Assumptions!$B$36 -> 1200
A12: Scenario A: Small Signal (1K BTC)
A13: Loss Driver | B13: Bear $250M TVL | C13: Base $1B TVL | D13: Growth $2.5B TVL | E13: Bull $5B TVL | F13: Hyper $10B TVL
A14: Tier 1: BTC absorbed by IF ($M) | B14: =B8 -> 22.5 | C14: =C8 -> 90 | D14: =D8 -> 225 | E14: =E8 -> 450 | F14: =F8 -> 900
A15: Tier 1: Drop during IF holding period | B15: ='Dump Scenarios'!$B$14 -> -0.05 | C15: ='Dump Scenarios'!$B$14 -> -0.05 | D15: ='Dump Scenarios'!$B$14 -> -0.05 | E15: ='Dump Scenarios'!$B$14 -> -0.05 | F15: ='Dump Scenarios'!$B$14 -> -0.05
A16: Tier 1: IF Loss ($M) | B16: =B14*ABS(B15) -> 1.125 | C16: =C14*ABS(C15) -> 4.5 | D16: =D14*ABS(D15) -> 11.25 | E16: =E14*ABS(E15) -> 22.5 | F16: =F14*ABS(F15) -> 45
A17: Tier 2: DEX slippage cost ($M) | B17: =B9*ABS('Dump Scenarios'!$B$15) -> 0.975 | C17: =C9*ABS('Dump Scenarios'!$B$15) -> 3.9 | D17: =D9*ABS('Dump Scenarios'!$B$15) -> 9.75 | E17: =E9*ABS('Dump Scenarios'!$B$15) -> 19.5 | F17: =F9*ABS('Dump Scenarios'!$B$15) -> 39
A18: Tier 3: Auctioneer shortfall ($M) | B18: =B10*ABS('Dump Scenarios'!$B$16) -> 0.9 | C18: =C10*ABS('Dump Scenarios'!$B$16) -> 3.6 | D18: =D10*ABS('Dump Scenarios'!$B$16) -> 9 | E18: =E10*ABS('Dump Scenarios'!$B$16) -> 18 | F18: =F10*ABS('Dump Scenarios'!$B$16) -> 36
A19: ── Total IF Liability ($M) | B19: =B16+B17+B18 -> 3 | C19: =C16+C17+C18 -> 12 | D19: =D16+D17+D18 -> 30 | E19: =E16+E17+E18 -> 60 | F19: =F16+F17+F18 -> 120
A20: ── Required IF / TVL (%) | B20: =B19/B6 -> 0.012 | C20: =C19/C6 -> 0.012 | D20: =D19/D6 -> 0.012 | E20: =E19/E6 -> 0.012 | F20: =F19/F6 -> 0.012
A21: → Check: Is 1% enrollment sufficient? | B21: =IF(B20<=0.01,"✅ YES — 1% covers it",IF(B20<=0.05,"⚠️ NO — need "&TEXT(B20,"0.0%"),"🔴 NO — need "&TEXT(B20,"0.0%"))) -> ⚠️ NO — need 1.2% | C21: =IF(C20<=0.01,"✅ YES — 1% covers it",IF(C20<=0.05,"⚠️ NO — need "&TEXT(C20,"0.0%"),"🔴 NO — need "&TEXT(C20,"0.0%"))) -> ⚠️ NO — need 1.2% | D21: =IF(D20<=0.01,"✅ YES — 1% covers it",IF(D20<=0.05,"⚠️ NO — need "&TEXT(D20,"0.0%"),"🔴 NO — need "&TEXT(D20,"0.0%"))) -> ⚠️ NO — need 1.2% | E21: =IF(E20<=0.01,"✅ YES — 1% covers it",IF(E20<=0.05,"⚠️ NO — need "&TEXT(E20,"0.0%"),"🔴 NO — need "&TEXT(E20,"0.0%"))) -> ⚠️ NO — need 1.2% | F21: =IF(F20<=0.01,"✅ YES — 1% covers it",IF(F20<=0.05,"⚠️ NO — need "&TEXT(F20,"0.0%"),"🔴 NO — need "&TEXT(F20,"0.0%"))) -> ⚠️ NO — need 1.2%
A23: Scenario B: Moderate (10K BTC)
A24: Loss Driver | B24: Bear $250M TVL | C24: Base $1B TVL | D24: Growth $2.5B TVL | E24: Bull $5B TVL | F24: Hyper $10B TVL
A25: Tier 1: BTC absorbed by IF ($M) | B25: =B8 -> 22.5 | C25: =C8 -> 90 | D25: =D8 -> 225 | E25: =E8 -> 450 | F25: =F8 -> 900
A26: Tier 1: Drop during IF holding period | B26: ='Dump Scenarios'!$C$14 -> -0.15 | C26: ='Dump Scenarios'!$C$14 -> -0.15 | D26: ='Dump Scenarios'!$C$14 -> -0.15 | E26: ='Dump Scenarios'!$C$14 -> -0.15 | F26: ='Dump Scenarios'!$C$14 -> -0.15
A27: Tier 1: IF Loss ($M) | B27: =B25*ABS(B26) -> 3.375 | C27: =C25*ABS(C26) -> 13.5 | D27: =D25*ABS(D26) -> 33.75 | E27: =E25*ABS(E26) -> 67.5 | F27: =F25*ABS(F26) -> 135
A28: Tier 2: DEX slippage cost ($M) | B28: =B9*ABS('Dump Scenarios'!$C$15) -> 4.875 | C28: =C9*ABS('Dump Scenarios'!$C$15) -> 19.5 | D28: =D9*ABS('Dump Scenarios'!$C$15) -> 48.75 | E28: =E9*ABS('Dump Scenarios'!$C$15) -> 97.5 | F28: =F9*ABS('Dump Scenarios'!$C$15) -> 195
A29: Tier 3: Auctioneer shortfall ($M) | B29: =B10*ABS('Dump Scenarios'!$C$16) -> 2.4 | C29: =C10*ABS('Dump Scenarios'!$C$16) -> 9.6 | D29: =D10*ABS('Dump Scenarios'!$C$16) -> 24 | E29: =E10*ABS('Dump Scenarios'!$C$16) -> 48 | F29: =F10*ABS('Dump Scenarios'!$C$16) -> 96
A30: ── Total IF Liability ($M) | B30: =B27+B28+B29 -> 10.65 | C30: =C27+C28+C29 -> 42.6 | D30: =D27+D28+D29 -> 106.5 | E30: =E27+E28+E29 -> 213 | F30: =F27+F28+F29 -> 426
A31: ── Required IF / TVL (%) | B31: =B30/B6 -> 0.0426 | C31: =C30/C6 -> 0.0426 | D31: =D30/D6 -> 0.0426 | E31: =E30/E6 -> 0.0426 | F31: =F30/F6 -> 0.0426
A32: → Check: Is 1% enrollment sufficient? | B32: =IF(B31<=0.01,"✅ YES — 1% covers it",IF(B31<=0.05,"⚠️ NO — need "&TEXT(B31,"0.0%"),"🔴 NO — need "&TEXT(B31,"0.0%"))) -> ⚠️ NO — need 4.3% | C32: =IF(C31<=0.01,"✅ YES — 1% covers it",IF(C31<=0.05,"⚠️ NO — need "&TEXT(C31,"0.0%"),"🔴 NO — need "&TEXT(C31,"0.0%"))) -> ⚠️ NO — need 4.3% | D32: =IF(D31<=0.01,"✅ YES — 1% covers it",IF(D31<=0.05,"⚠️ NO — need "&TEXT(D31,"0.0%"),"🔴 NO — need "&TEXT(D31,"0.0%"))) -> ⚠️ NO — need 4.3% | E32: =IF(E31<=0.01,"✅ YES — 1% covers it",IF(E31<=0.05,"⚠️ NO — need "&TEXT(E31,"0.0%"),"🔴 NO — need "&TEXT(E31,"0.0%"))) -> ⚠️ NO — need 4.3% | F32: =IF(F31<=0.01,"✅ YES — 1% covers it",IF(F31<=0.05,"⚠️ NO — need "&TEXT(F31,"0.0%"),"🔴 NO — need "&TEXT(F31,"0.0%"))) -> ⚠️ NO — need 4.3%
A34: Scenario C: Large (100K BTC)
A35: Loss Driver | B35: Bear $250M TVL | C35: Base $1B TVL | D35: Growth $2.5B TVL | E35: Bull $5B TVL | F35: Hyper $10B TVL
A36: Tier 1: BTC absorbed by IF ($M) | B36: =B8 -> 22.5 | C36: =C8 -> 90 | D36: =D8 -> 225 | E36: =E8 -> 450 | F36: =F8 -> 900
A37: Tier 1: Drop during IF holding period | B37: ='Dump Scenarios'!$D$14 -> -0.25 | C37: ='Dump Scenarios'!$D$14 -> -0.25 | D37: ='Dump Scenarios'!$D$14 -> -0.25 | E37: ='Dump Scenarios'!$D$14 -> -0.25 | F37: ='Dump Scenarios'!$D$14 -> -0.25
A38: Tier 1: IF Loss ($M) | B38: =B36*ABS(B37) -> 5.625 | C38: =C36*ABS(C37) -> 22.5 | D38: =D36*ABS(D37) -> 56.25 | E38: =E36*ABS(E37) -> 112.5 | F38: =F36*ABS(F37) -> 225
A39: Tier 2: DEX slippage cost ($M) | B39: =B9*ABS('Dump Scenarios'!$D$15) -> 9.75 | C39: =C9*ABS('Dump Scenarios'!$D$15) -> 39 | D39: =D9*ABS('Dump Scenarios'!$D$15) -> 97.5 | E39: =E9*ABS('Dump Scenarios'!$D$15) -> 195 | F39: =F9*ABS('Dump Scenarios'!$D$15) -> 390
A40: Tier 3: Auctioneer shortfall ($M) | B40: =B10*ABS('Dump Scenarios'!$D$16) -> 4.5 | C40: =C10*ABS('Dump Scenarios'!$D$16) -> 18 | D40: =D10*ABS('Dump Scenarios'!$D$16) -> 45 | E40: =E10*ABS('Dump Scenarios'!$D$16) -> 90 | F40: =F10*ABS('Dump Scenarios'!$D$16) -> 180
A41: ── Total IF Liability ($M) | B41: =B38+B39+B40 -> 19.875 | C41: =C38+C39+C40 -> 79.5 | D41: =D38+D39+D40 -> 198.75 | E41: =E38+E39+E40 -> 397.5 | F41: =F38+F39+F40 -> 795
A42: ── Required IF / TVL (%) | B42: =B41/B6 -> 0.0795 | C42: =C41/C6 -> 0.0795 | D42: =D41/D6 -> 0.0795 | E42: =E41/E6 -> 0.0795 | F42: =F41/F6 -> 0.0795
A43: → Check: Is 1% enrollment sufficient? | B43: =IF(B42<=0.01,"✅ YES — 1% covers it",IF(B42<=0.05,"⚠️ NO — need "&TEXT(B42,"0.0%"),"🔴 NO — need "&TEXT(B42,"0.0%"))) -> 🔴 NO — need 8.0% | C43: =IF(C42<=0.01,"✅ YES — 1% covers it",IF(C42<=0.05,"⚠️ NO — need "&TEXT(C42,"0.0%"),"🔴 NO — need "&TEXT(C42,"0.0%"))) -> 🔴 NO — need 8.0% | D43: =IF(D42<=0.01,"✅ YES — 1% covers it",IF(D42<=0.05,"⚠️ NO — need "&TEXT(D42,"0.0%"),"🔴 NO — need "&TEXT(D42,"0.0%"))) -> 🔴 NO — need 8.0% | E43: =IF(E42<=0.01,"✅ YES — 1% covers it",IF(E42<=0.05,"⚠️ NO — need "&TEXT(E42,"0.0%"),"🔴 NO — need "&TEXT(E42,"0.0%"))) -> 🔴 NO — need 8.0% | F43: =IF(F42<=0.01,"✅ YES — 1% covers it",IF(F42<=0.05,"⚠️ NO — need "&TEXT(F42,"0.0%"),"🔴 NO — need "&TEXT(F42,"0.0%"))) -> 🔴 NO — need 8.0%
A45: Scenario D: Catastrophic (500K BTC)
...

Sheet Fee Calibration
A1: FEE CALIBRATION — Enrollment Premium & IF Buildup
A2: How quickly does the IF reach target size, and what fee structure gets us there?
A4: FEE ASSUMPTIONS (Blue = editable inputs)
A5: Parameter | B5: Value | C5: Unit | D5: Notes
A6: Enrollment Premium (one-time, % of deposit) | B6: 0.005 | C6: % | D6: SSL spec range: 0.25–1.00%; default 0.50%
A7: Ongoing Annual Fee (% of AUM) | B7: 0.001 | C7: %/yr | D7: SSL spec range: 5–20 bps/yr; default 10 bps
A8: Auctioneer Rev Share → IF | B8: 0.1 | C8: % | D8: Fixed at 10% per OQ-1 protocol design
A9: Target IF / TVL Ratio | B9: 0.05 | C9: % | D9: 5% = covers Scenario B (moderate event)
A10: Protocol Seed Capital ($M) | B10: 5 | C10: $M | D10: From founding team / early backers
A11: IF Retention (% of inflows kept in reserve) | B11: 0.5 | C11: % | D11: 50% retained; 50% to stakers per OQ-1
A13: IF RESERVE BUILDUP — Years to Reach Target IF/TVL
A14: Metric | B14: $250M TVL | C14: $500M TVL | D14: $1B TVL | E14: $2.5B TVL | F14: $5B TVL
A15: Target IF Size ($M) | B15: =250*$B$9 -> 12.5 | C15: =500*$B$9 -> 25 | D15: =1000*$B$9 -> 50 | E15: =2500*$B$9 -> 125 | F15: =5000*$B$9 -> 250
A16: Annual Enrollment Inflow ($M) [retained portion] | B16: =250*$B$6*$B$11 -> 0.625 | C16: =500*$B$6*$B$11 -> 1.25 | D16: =1000*$B$6*$B$11 -> 2.5 | E16: =2500*$B$6*$B$11 -> 6.25 | F16: =5000*$B$6*$B$11 -> 12.5
A17: Annual Ongoing Fee Inflow ($M) [retained portion] | B17: =250*$B$7*$B$11 -> 0.125 | C17: =500*$B$7*$B$11 -> 0.25 | D17: =1000*$B$7*$B$11 -> 0.5 | E17: =2500*$B$7*$B$11 -> 1.25 | F17: =5000*$B$7*$B$11 -> 2.5
A18: Total Annual IF Inflow ($M/yr) | B18: =B16+B17 -> 0.75 | C18: =C16+C17 -> 1.5 | D18: =D16+D17 -> 3 | E18: =E16+E17 -> 7.5 | F18: =F16+F17 -> 15
A19: Protocol Seed Capital ($M) | B19: =$B$10 -> 5 | C19: =$B$10 -> 5 | D19: =$B$10 -> 5 | E19: =$B$10 -> 5 | F19: =$B$10 -> 5
A20: → Years to Reach Target | B20: =IF(B18=0,999,MAX(0,(B15-B19)/B18)) -> 10 | C20: =IF(C18=0,999,MAX(0,(C15-C19)/C18)) -> 13.333333 | D20: =IF(D18=0,999,MAX(0,(D15-D19)/D18)) -> 15 | E20: =IF(E18=0,999,MAX(0,(E15-E19)/E18)) -> 16 | F20: =IF(F18=0,999,MAX(0,(F15-F19)/F18)) -> 16.333333
A21: Green < 3 yrs | Yellow 3–5 yrs | Red > 5 yrs
A23: SENSITIVITY MATRIX: Years to Reach 5% IF Target | $1B TVL, $5M Seed, 50% Retention
A24: Ongoing Fee (bps) \ Enrollment → | B24: Enroll 0.25% | C24: Enroll 0.50% | D24: Enroll 0.75% | E24: Enroll 1.00% | F24: Enroll 1.50%
A25: 5 bps/yr | B25: 30 | C25: 16.4 | D25: 11.2 | E25: 8.6 | F25: 5.8
A26: 10 bps/yr | B26: 25.7 | C26: 15 | D26: 10.6 | E26: 8.2 | F26: 5.6
A27: 15 bps/yr | B27: 22.5 | C27: 13.8 | D27: 10 | E27: 7.8 | F27: 5.5
A28: 20 bps/yr | B28: 20 | C28: 12.9 | D28: 9.5 | E28: 7.5 | F28: 5.3
A29: 30 bps/yr | B29: 16.4 | C29: 11.2 | D29: 8.6 | E29: 6.9 | F29: 5
A30: Green ≤ 3 yrs | Yellow 3–5 yrs | Red > 5 yrs (Base: $1B TVL, $5M seed, 5% IF target, 50% retention)
A32: COMPARABLE PROTOCOL COVERAGE BENCHMARKS
A33: Protocol | B33: Type | C33: Entry Fee | D33: Annual Fee | E33: IF/Reserve Ratio
A34: Nexus Mutual | B34: Smart contract cover | C34: 0% | D34: <1.0% | E34: ~30% capital pool / coverage
A35: InsurAce | B35: Multi-chain DeFi cover | C35: 0% | D35: 0.5–3.0% | E35: ~20%
A36: Unslashed Finance | B36: Slashing cover | C36: 0% | D36: 1.0–2.0% | E36: ~25%
A37: Risk Harbor | B37: Parametric DeFi cover | C37: 0% | D37: 1.0–4.0% | E37: ~15%
A38: SSL (this model) | B38: Satoshi stop-loss | C38: 0.50% | D38: 0.10% | E38: Target 5%; tail risk 10–12%
